2025-08-31 02:22:56,959 - app.main - INFO - Starting Plant Whisperer Backend...
2025-08-31 02:22:56,961 - app.main - INFO - Backend startup complete
2025-08-31 02:23:02,257 - app.main - INFO - Starting Plant Whisperer Backend...
2025-08-31 02:23:02,260 - app.main - INFO - Backend startup complete
2025-08-31 02:24:00,909 - app.main - INFO - Starting Plant Whisperer Backend...
2025-08-31 02:24:00,912 - app.main - INFO - Backend startup complete
2025-08-31 02:30:51,318 - app.utils.io_utils - INFO - 파일 저장 완료: ./storage\e0082f30-631c-4129-8149-a1702cdd4953.jpg
2025-08-31 02:32:08,106 - app.services.preprocess - INFO - U²-Net 배경 제거 모델 로드 완료
2025-08-31 02:32:10,292 - app.services.classifier - ERROR - 기본 모델 로드 실패: Unknown model (efficientnet_b0_plant_whisperer)
2025-08-31 02:32:10,292 - app.services.classifier - ERROR - PyTorch 모델 로드 실패: Unknown model (efficientnet_b0_plant_whisperer)
2025-08-31 02:32:10,293 - app.services.classifier - ERROR - 기본 모델 로드 실패: Unknown model (efficientnet_b0_plant_whisperer)
2025-08-31 02:32:10,293 - app.services.classifier - ERROR - 모델 로드 실패: Unknown model (efficientnet_b0_plant_whisperer)
2025-08-31 02:32:10,297 - app.services.classifier - ERROR - 기본 모델 로드 실패: Unknown model (efficientnet_b0_plant_whisperer)
2025-08-31 02:32:10,297 - app.routers.infer - ERROR - Prediction error: Unknown model (efficientnet_b0_plant_whisperer)
Traceback (most recent call last):
  File "D:\Pland\backend\app\services\classifier.py", line 108, in _load_pytorch_model
    self._load_default_model()
  File "D:\Pland\backend\app\services\classifier.py", line 116, in _load_default_model
    self.model = timm.create_model(
                 ^^^^^^^^^^^^^^^^^^
  File "D:\Pland\venv\Lib\site-packages\timm\models\_factory.py", line 113, in create_model
    raise RuntimeError('Unknown model (%s)' % model_name)
RuntimeError: Unknown model (efficientnet_b0_plant_whisperer)

During handling of the above exception, another exception occurred:

Traceback (most recent call last):
  File "D:\Pland\backend\app\services\classifier.py", line 78, in _load_model
    self._load_pytorch_model()
  File "D:\Pland\backend\app\services\classifier.py", line 111, in _load_pytorch_model
    self._load_default_model()
  File "D:\Pland\backend\app\services\classifier.py", line 116, in _load_default_model
    self.model = timm.create_model(
                 ^^^^^^^^^^^^^^^^^^
  File "D:\Pland\venv\Lib\site-packages\timm\models\_factory.py", line 113, in create_model
    raise RuntimeError('Unknown model (%s)' % model_name)
RuntimeError: Unknown model (efficientnet_b0_plant_whisperer)

During handling of the above exception, another exception occurred:

Traceback (most recent call last):
  File "D:\Pland\backend\app\routers\infer.py", line 71, in predict_plant
    classifier = PlantClassifier(
                 ^^^^^^^^^^^^^^^^
  File "D:\Pland\backend\app\services\classifier.py", line 54, in __init__
    self._load_model()
  File "D:\Pland\backend\app\services\classifier.py", line 82, in _load_model
    self._load_default_model()
  File "D:\Pland\backend\app\services\classifier.py", line 116, in _load_default_model
    self.model = timm.create_model(
                 ^^^^^^^^^^^^^^^^^^
  File "D:\Pland\venv\Lib\site-packages\timm\models\_factory.py", line 113, in create_model
    raise RuntimeError('Unknown model (%s)' % model_name)
RuntimeError: Unknown model (efficientnet_b0_plant_whisperer)
2025-08-31 02:32:10,301 - app.main - ERROR - HTTP 500: 이미지 분석 중 오류가 발생했습니다.
2025-08-31 02:32:10,302 - app.main - ERROR - Unexpected error: 'dict' object is not callable
Traceback (most recent call last):
  File "D:\Pland\backend\app\services\classifier.py", line 108, in _load_pytorch_model
    self._load_default_model()
  File "D:\Pland\backend\app\services\classifier.py", line 116, in _load_default_model
    self.model = timm.create_model(
                 ^^^^^^^^^^^^^^^^^^
  File "D:\Pland\venv\Lib\site-packages\timm\models\_factory.py", line 113, in create_model
    raise RuntimeError('Unknown model (%s)' % model_name)
RuntimeError: Unknown model (efficientnet_b0_plant_whisperer)

During handling of the above exception, another exception occurred:

Traceback (most recent call last):
  File "D:\Pland\backend\app\services\classifier.py", line 78, in _load_model
    self._load_pytorch_model()
  File "D:\Pland\backend\app\services\classifier.py", line 111, in _load_pytorch_model
    self._load_default_model()
  File "D:\Pland\backend\app\services\classifier.py", line 116, in _load_default_model
    self.model = timm.create_model(
                 ^^^^^^^^^^^^^^^^^^
  File "D:\Pland\venv\Lib\site-packages\timm\models\_factory.py", line 113, in create_model
    raise RuntimeError('Unknown model (%s)' % model_name)
RuntimeError: Unknown model (efficientnet_b0_plant_whisperer)

During handling of the above exception, another exception occurred:

Traceback (most recent call last):
  File "D:\Pland\backend\app\routers\infer.py", line 71, in predict_plant
    classifier = PlantClassifier(
                 ^^^^^^^^^^^^^^^^
  File "D:\Pland\backend\app\services\classifier.py", line 54, in __init__
    self._load_model()
  File "D:\Pland\backend\app\services\classifier.py", line 82, in _load_model
    self._load_default_model()
  File "D:\Pland\backend\app\services\classifier.py", line 116, in _load_default_model
    self.model = timm.create_model(
                 ^^^^^^^^^^^^^^^^^^
  File "D:\Pland\venv\Lib\site-packages\timm\models\_factory.py", line 113, in create_model
    raise RuntimeError('Unknown model (%s)' % model_name)
RuntimeError: Unknown model (efficientnet_b0_plant_whisperer)

During handling of the above exception, another exception occurred:

Traceback (most recent call last):
  File "D:\Pland\venv\Lib\site-packages\starlette\middleware\exceptions.py", line 68, in __call__
    await self.app(scope, receive, sender)
  File "D:\Pland\venv\Lib\site-packages\fastapi\middleware\asyncexitstack.py", line 20, in __call__
    raise e
  File "D:\Pland\venv\Lib\site-packages\fastapi\middleware\asyncexitstack.py", line 17, in __call__
    await self.app(scope, receive, send)
  File "D:\Pland\venv\Lib\site-packages\starlette\routing.py", line 718, in __call__
    await route.handle(scope, receive, send)
  File "D:\Pland\venv\Lib\site-packages\starlette\routing.py", line 276, in handle
    await self.app(scope, receive, send)
  File "D:\Pland\venv\Lib\site-packages\starlette\routing.py", line 66, in app
    response = await func(request)
               ^^^^^^^^^^^^^^^^^^^
  File "D:\Pland\venv\Lib\site-packages\fastapi\routing.py", line 274, in app
    raw_response = await run_endpoint_function(
                   ^^^^^^^^^^^^^^^^^^^^^^^^^^^^
  File "D:\Pland\venv\Lib\site-packages\fastapi\routing.py", line 191, in run_endpoint_function
    return await dependant.call(**values)
           ^^^^^^^^^^^^^^^^^^^^^^^^^^^^^^
  File "D:\Pland\backend\app\routers\infer.py", line 118, in predict_plant
    raise HTTPException(
fastapi.exceptions.HTTPException

During handling of the above exception, another exception occurred:

Traceback (most recent call last):
  File "D:\Pland\venv\Lib\site-packages\starlette\middleware\errors.py", line 162, in __call__
    await self.app(scope, receive, _send)
  File "D:\Pland\venv\Lib\site-packages\starlette\middleware\cors.py", line 91, in __call__
    await self.simple_response(scope, receive, send, request_headers=headers)
  File "D:\Pland\venv\Lib\site-packages\starlette\middleware\cors.py", line 146, in simple_response
    await self.app(scope, receive, send)
  File "D:\Pland\venv\Lib\site-packages\starlette\middleware\exceptions.py", line 91, in __call__
    await response(scope, receive, sender)
          ^^^^^^^^^^^^^^^^^^^^^^^^^^^^^^^^
TypeError: 'dict' object is not callable
2025-08-31 02:32:10,339 - app.utils.io_utils - INFO - 파일 저장 완료: ./storage\e71bdbf4-dccb-4ec7-8a7b-2f9720c1290b.jpg
2025-08-31 02:32:10,345 - app.services.preprocess - INFO - U²-Net 배경 제거 모델 로드 완료
2025-08-31 02:32:12,348 - app.services.classifier - ERROR - 기본 모델 로드 실패: Unknown model (efficientnet_b0_plant_whisperer)
2025-08-31 02:32:12,349 - app.services.classifier - ERROR - PyTorch 모델 로드 실패: Unknown model (efficientnet_b0_plant_whisperer)
2025-08-31 02:32:12,349 - app.services.classifier - ERROR - 기본 모델 로드 실패: Unknown model (efficientnet_b0_plant_whisperer)
2025-08-31 02:32:12,350 - app.services.classifier - ERROR - 모델 로드 실패: Unknown model (efficientnet_b0_plant_whisperer)
2025-08-31 02:32:12,350 - app.services.classifier - ERROR - 기본 모델 로드 실패: Unknown model (efficientnet_b0_plant_whisperer)
2025-08-31 02:32:12,350 - app.routers.infer - ERROR - Prediction error: Unknown model (efficientnet_b0_plant_whisperer)
Traceback (most recent call last):
  File "D:\Pland\backend\app\services\classifier.py", line 108, in _load_pytorch_model
    self._load_default_model()
  File "D:\Pland\backend\app\services\classifier.py", line 116, in _load_default_model
    self.model = timm.create_model(
                 ^^^^^^^^^^^^^^^^^^
  File "D:\Pland\venv\Lib\site-packages\timm\models\_factory.py", line 113, in create_model
    raise RuntimeError('Unknown model (%s)' % model_name)
RuntimeError: Unknown model (efficientnet_b0_plant_whisperer)

During handling of the above exception, another exception occurred:

Traceback (most recent call last):
  File "D:\Pland\backend\app\services\classifier.py", line 78, in _load_model
    self._load_pytorch_model()
  File "D:\Pland\backend\app\services\classifier.py", line 111, in _load_pytorch_model
    self._load_default_model()
  File "D:\Pland\backend\app\services\classifier.py", line 116, in _load_default_model
    self.model = timm.create_model(
                 ^^^^^^^^^^^^^^^^^^
  File "D:\Pland\venv\Lib\site-packages\timm\models\_factory.py", line 113, in create_model
    raise RuntimeError('Unknown model (%s)' % model_name)
RuntimeError: Unknown model (efficientnet_b0_plant_whisperer)

During handling of the above exception, another exception occurred:

Traceback (most recent call last):
  File "D:\Pland\backend\app\routers\infer.py", line 71, in predict_plant
    classifier = PlantClassifier(
                 ^^^^^^^^^^^^^^^^
  File "D:\Pland\backend\app\services\classifier.py", line 54, in __init__
    self._load_model()
  File "D:\Pland\backend\app\services\classifier.py", line 82, in _load_model
    self._load_default_model()
  File "D:\Pland\backend\app\services\classifier.py", line 116, in _load_default_model
    self.model = timm.create_model(
                 ^^^^^^^^^^^^^^^^^^
  File "D:\Pland\venv\Lib\site-packages\timm\models\_factory.py", line 113, in create_model
    raise RuntimeError('Unknown model (%s)' % model_name)
RuntimeError: Unknown model (efficientnet_b0_plant_whisperer)
2025-08-31 02:32:12,353 - app.main - ERROR - HTTP 500: 이미지 분석 중 오류가 발생했습니다.
2025-08-31 02:32:12,354 - app.main - ERROR - Unexpected error: 'dict' object is not callable
Traceback (most recent call last):
  File "D:\Pland\backend\app\services\classifier.py", line 108, in _load_pytorch_model
    self._load_default_model()
  File "D:\Pland\backend\app\services\classifier.py", line 116, in _load_default_model
    self.model = timm.create_model(
                 ^^^^^^^^^^^^^^^^^^
  File "D:\Pland\venv\Lib\site-packages\timm\models\_factory.py", line 113, in create_model
    raise RuntimeError('Unknown model (%s)' % model_name)
RuntimeError: Unknown model (efficientnet_b0_plant_whisperer)

During handling of the above exception, another exception occurred:

Traceback (most recent call last):
  File "D:\Pland\backend\app\services\classifier.py", line 78, in _load_model
    self._load_pytorch_model()
  File "D:\Pland\backend\app\services\classifier.py", line 111, in _load_pytorch_model
    self._load_default_model()
  File "D:\Pland\backend\app\services\classifier.py", line 116, in _load_default_model
    self.model = timm.create_model(
                 ^^^^^^^^^^^^^^^^^^
  File "D:\Pland\venv\Lib\site-packages\timm\models\_factory.py", line 113, in create_model
    raise RuntimeError('Unknown model (%s)' % model_name)
RuntimeError: Unknown model (efficientnet_b0_plant_whisperer)

During handling of the above exception, another exception occurred:

Traceback (most recent call last):
  File "D:\Pland\backend\app\routers\infer.py", line 71, in predict_plant
    classifier = PlantClassifier(
                 ^^^^^^^^^^^^^^^^
  File "D:\Pland\backend\app\services\classifier.py", line 54, in __init__
    self._load_model()
  File "D:\Pland\backend\app\services\classifier.py", line 82, in _load_model
    self._load_default_model()
  File "D:\Pland\backend\app\services\classifier.py", line 116, in _load_default_model
    self.model = timm.create_model(
                 ^^^^^^^^^^^^^^^^^^
  File "D:\Pland\venv\Lib\site-packages\timm\models\_factory.py", line 113, in create_model
    raise RuntimeError('Unknown model (%s)' % model_name)
RuntimeError: Unknown model (efficientnet_b0_plant_whisperer)

During handling of the above exception, another exception occurred:

Traceback (most recent call last):
  File "D:\Pland\venv\Lib\site-packages\starlette\middleware\exceptions.py", line 68, in __call__
    await self.app(scope, receive, sender)
  File "D:\Pland\venv\Lib\site-packages\fastapi\middleware\asyncexitstack.py", line 20, in __call__
    raise e
  File "D:\Pland\venv\Lib\site-packages\fastapi\middleware\asyncexitstack.py", line 17, in __call__
    await self.app(scope, receive, send)
  File "D:\Pland\venv\Lib\site-packages\starlette\routing.py", line 718, in __call__
    await route.handle(scope, receive, send)
  File "D:\Pland\venv\Lib\site-packages\starlette\routing.py", line 276, in handle
    await self.app(scope, receive, send)
  File "D:\Pland\venv\Lib\site-packages\starlette\routing.py", line 66, in app
    response = await func(request)
               ^^^^^^^^^^^^^^^^^^^
  File "D:\Pland\venv\Lib\site-packages\fastapi\routing.py", line 274, in app
    raw_response = await run_endpoint_function(
                   ^^^^^^^^^^^^^^^^^^^^^^^^^^^^
  File "D:\Pland\venv\Lib\site-packages\fastapi\routing.py", line 191, in run_endpoint_function
    return await dependant.call(**values)
           ^^^^^^^^^^^^^^^^^^^^^^^^^^^^^^
  File "D:\Pland\backend\app\routers\infer.py", line 118, in predict_plant
    raise HTTPException(
fastapi.exceptions.HTTPException

During handling of the above exception, another exception occurred:

Traceback (most recent call last):
  File "D:\Pland\venv\Lib\site-packages\starlette\middleware\errors.py", line 162, in __call__
    await self.app(scope, receive, _send)
  File "D:\Pland\venv\Lib\site-packages\starlette\middleware\cors.py", line 91, in __call__
    await self.simple_response(scope, receive, send, request_headers=headers)
  File "D:\Pland\venv\Lib\site-packages\starlette\middleware\cors.py", line 146, in simple_response
    await self.app(scope, receive, send)
  File "D:\Pland\venv\Lib\site-packages\starlette\middleware\exceptions.py", line 91, in __call__
    await response(scope, receive, sender)
          ^^^^^^^^^^^^^^^^^^^^^^^^^^^^^^^^
TypeError: 'dict' object is not callable
2025-08-31 02:32:12,372 - app.main - INFO - Shutting down Plant Whisperer Backend...
2025-08-31 02:32:20,920 - app.main - INFO - Starting Plant Whisperer Backend...
2025-08-31 02:32:20,924 - app.main - INFO - Backend startup complete
2025-08-31 02:32:20,941 - app.utils.io_utils - INFO - 파일 저장 완료: ./storage\f961bf11-d76e-4894-be75-b78f0307ffc9.jpg
2025-08-31 02:32:22,860 - app.services.preprocess - INFO - U²-Net 배경 제거 모델 로드 완료
2025-08-31 02:32:24,657 - app.services.classifier - ERROR - 기본 모델 로드 실패: Unknown model (efficientnet_b0_plant_whisperer)
2025-08-31 02:32:24,658 - app.services.classifier - ERROR - PyTorch 모델 로드 실패: Unknown model (efficientnet_b0_plant_whisperer)
2025-08-31 02:32:24,658 - app.services.classifier - ERROR - 기본 모델 로드 실패: Unknown model (efficientnet_b0_plant_whisperer)
2025-08-31 02:32:24,658 - app.services.classifier - ERROR - 모델 로드 실패: Unknown model (efficientnet_b0_plant_whisperer)
2025-08-31 02:32:24,660 - app.services.classifier - ERROR - 기본 모델 로드 실패: Unknown model (efficientnet_b0_plant_whisperer)
2025-08-31 02:32:24,660 - app.routers.infer - ERROR - Prediction error: Unknown model (efficientnet_b0_plant_whisperer)
Traceback (most recent call last):
  File "D:\Pland\backend\app\services\classifier.py", line 108, in _load_pytorch_model
    self._load_default_model()
  File "D:\Pland\backend\app\services\classifier.py", line 116, in _load_default_model
    self.model = timm.create_model(
                 ^^^^^^^^^^^^^^^^^^
  File "D:\Pland\venv\Lib\site-packages\timm\models\_factory.py", line 113, in create_model
    raise RuntimeError('Unknown model (%s)' % model_name)
RuntimeError: Unknown model (efficientnet_b0_plant_whisperer)

During handling of the above exception, another exception occurred:

Traceback (most recent call last):
  File "D:\Pland\backend\app\services\classifier.py", line 78, in _load_model
    self._load_pytorch_model()
  File "D:\Pland\backend\app\services\classifier.py", line 111, in _load_pytorch_model
    self._load_default_model()
  File "D:\Pland\backend\app\services\classifier.py", line 116, in _load_default_model
    self.model = timm.create_model(
                 ^^^^^^^^^^^^^^^^^^
  File "D:\Pland\venv\Lib\site-packages\timm\models\_factory.py", line 113, in create_model
    raise RuntimeError('Unknown model (%s)' % model_name)
RuntimeError: Unknown model (efficientnet_b0_plant_whisperer)

During handling of the above exception, another exception occurred:

Traceback (most recent call last):
  File "D:\Pland\backend\app\routers\infer.py", line 71, in predict_plant
    classifier = PlantClassifier(
                 ^^^^^^^^^^^^^^^^
  File "D:\Pland\backend\app\services\classifier.py", line 54, in __init__
    self._load_model()
  File "D:\Pland\backend\app\services\classifier.py", line 82, in _load_model
    self._load_default_model()
  File "D:\Pland\backend\app\services\classifier.py", line 116, in _load_default_model
    self.model = timm.create_model(
                 ^^^^^^^^^^^^^^^^^^
  File "D:\Pland\venv\Lib\site-packages\timm\models\_factory.py", line 113, in create_model
    raise RuntimeError('Unknown model (%s)' % model_name)
RuntimeError: Unknown model (efficientnet_b0_plant_whisperer)
2025-08-31 02:32:24,664 - app.main - ERROR - HTTP 500: 이미지 분석 중 오류가 발생했습니다.
2025-08-31 02:32:24,664 - app.main - ERROR - Unexpected error: 'dict' object is not callable
Traceback (most recent call last):
  File "D:\Pland\backend\app\services\classifier.py", line 108, in _load_pytorch_model
    self._load_default_model()
  File "D:\Pland\backend\app\services\classifier.py", line 116, in _load_default_model
    self.model = timm.create_model(
                 ^^^^^^^^^^^^^^^^^^
  File "D:\Pland\venv\Lib\site-packages\timm\models\_factory.py", line 113, in create_model
    raise RuntimeError('Unknown model (%s)' % model_name)
RuntimeError: Unknown model (efficientnet_b0_plant_whisperer)

During handling of the above exception, another exception occurred:

Traceback (most recent call last):
  File "D:\Pland\backend\app\services\classifier.py", line 78, in _load_model
    self._load_pytorch_model()
  File "D:\Pland\backend\app\services\classifier.py", line 111, in _load_pytorch_model
    self._load_default_model()
  File "D:\Pland\backend\app\services\classifier.py", line 116, in _load_default_model
    self.model = timm.create_model(
                 ^^^^^^^^^^^^^^^^^^
  File "D:\Pland\venv\Lib\site-packages\timm\models\_factory.py", line 113, in create_model
    raise RuntimeError('Unknown model (%s)' % model_name)
RuntimeError: Unknown model (efficientnet_b0_plant_whisperer)

During handling of the above exception, another exception occurred:

Traceback (most recent call last):
  File "D:\Pland\backend\app\routers\infer.py", line 71, in predict_plant
    classifier = PlantClassifier(
                 ^^^^^^^^^^^^^^^^
  File "D:\Pland\backend\app\services\classifier.py", line 54, in __init__
    self._load_model()
  File "D:\Pland\backend\app\services\classifier.py", line 82, in _load_model
    self._load_default_model()
  File "D:\Pland\backend\app\services\classifier.py", line 116, in _load_default_model
    self.model = timm.create_model(
                 ^^^^^^^^^^^^^^^^^^
  File "D:\Pland\venv\Lib\site-packages\timm\models\_factory.py", line 113, in create_model
    raise RuntimeError('Unknown model (%s)' % model_name)
RuntimeError: Unknown model (efficientnet_b0_plant_whisperer)

During handling of the above exception, another exception occurred:

Traceback (most recent call last):
  File "D:\Pland\venv\Lib\site-packages\starlette\middleware\exceptions.py", line 68, in __call__
    await self.app(scope, receive, sender)
  File "D:\Pland\venv\Lib\site-packages\fastapi\middleware\asyncexitstack.py", line 20, in __call__
    raise e
  File "D:\Pland\venv\Lib\site-packages\fastapi\middleware\asyncexitstack.py", line 17, in __call__
    await self.app(scope, receive, send)
  File "D:\Pland\venv\Lib\site-packages\starlette\routing.py", line 718, in __call__
    await route.handle(scope, receive, send)
  File "D:\Pland\venv\Lib\site-packages\starlette\routing.py", line 276, in handle
    await self.app(scope, receive, send)
  File "D:\Pland\venv\Lib\site-packages\starlette\routing.py", line 66, in app
    response = await func(request)
               ^^^^^^^^^^^^^^^^^^^
  File "D:\Pland\venv\Lib\site-packages\fastapi\routing.py", line 274, in app
    raw_response = await run_endpoint_function(
                   ^^^^^^^^^^^^^^^^^^^^^^^^^^^^
  File "D:\Pland\venv\Lib\site-packages\fastapi\routing.py", line 191, in run_endpoint_function
    return await dependant.call(**values)
           ^^^^^^^^^^^^^^^^^^^^^^^^^^^^^^
  File "D:\Pland\backend\app\routers\infer.py", line 118, in predict_plant
    raise HTTPException(
fastapi.exceptions.HTTPException

During handling of the above exception, another exception occurred:

Traceback (most recent call last):
  File "D:\Pland\venv\Lib\site-packages\starlette\middleware\errors.py", line 162, in __call__
    await self.app(scope, receive, _send)
  File "D:\Pland\venv\Lib\site-packages\starlette\middleware\cors.py", line 91, in __call__
    await self.simple_response(scope, receive, send, request_headers=headers)
  File "D:\Pland\venv\Lib\site-packages\starlette\middleware\cors.py", line 146, in simple_response
    await self.app(scope, receive, send)
  File "D:\Pland\venv\Lib\site-packages\starlette\middleware\exceptions.py", line 91, in __call__
    await response(scope, receive, sender)
          ^^^^^^^^^^^^^^^^^^^^^^^^^^^^^^^^
TypeError: 'dict' object is not callable
2025-08-31 02:32:27,112 - app.main - INFO - Shutting down Plant Whisperer Backend...
2025-08-31 02:32:37,250 - app.main - INFO - Starting Plant Whisperer Backend...
2025-08-31 02:32:37,252 - app.main - INFO - Backend startup complete
2025-08-31 02:32:43,089 - app.utils.io_utils - INFO - 파일 저장 완료: ./storage\542abde3-57b9-444c-a56c-2aac46aeb6c5.jpg
2025-08-31 02:32:44,516 - app.services.preprocess - INFO - U²-Net 배경 제거 모델 로드 완료
2025-08-31 02:32:46,340 - app.services.classifier - ERROR - 기본 모델 로드 실패: Unknown model (efficientnet_b0_plant_whisperer)
2025-08-31 02:32:46,340 - app.services.classifier - ERROR - PyTorch 모델 로드 실패: Unknown model (efficientnet_b0_plant_whisperer)
2025-08-31 02:32:46,340 - app.services.classifier - ERROR - 기본 모델 로드 실패: Unknown model (efficientnet_b0_plant_whisperer)
2025-08-31 02:32:46,340 - app.services.classifier - ERROR - 모델 로드 실패: Unknown model (efficientnet_b0_plant_whisperer)
2025-08-31 02:32:46,341 - app.services.classifier - ERROR - 기본 모델 로드 실패: Unknown model (efficientnet_b0_plant_whisperer)
2025-08-31 02:32:46,341 - app.routers.infer - ERROR - Prediction error: Unknown model (efficientnet_b0_plant_whisperer)
Traceback (most recent call last):
  File "D:\Pland\backend\app\services\classifier.py", line 108, in _load_pytorch_model
    self._load_default_model()
  File "D:\Pland\backend\app\services\classifier.py", line 116, in _load_default_model
    self.model = timm.create_model(
                 ^^^^^^^^^^^^^^^^^^
  File "D:\Pland\venv\Lib\site-packages\timm\models\_factory.py", line 113, in create_model
    raise RuntimeError('Unknown model (%s)' % model_name)
RuntimeError: Unknown model (efficientnet_b0_plant_whisperer)

During handling of the above exception, another exception occurred:

Traceback (most recent call last):
  File "D:\Pland\backend\app\services\classifier.py", line 78, in _load_model
    self._load_pytorch_model()
  File "D:\Pland\backend\app\services\classifier.py", line 111, in _load_pytorch_model
    self._load_default_model()
  File "D:\Pland\backend\app\services\classifier.py", line 116, in _load_default_model
    self.model = timm.create_model(
                 ^^^^^^^^^^^^^^^^^^
  File "D:\Pland\venv\Lib\site-packages\timm\models\_factory.py", line 113, in create_model
    raise RuntimeError('Unknown model (%s)' % model_name)
RuntimeError: Unknown model (efficientnet_b0_plant_whisperer)

During handling of the above exception, another exception occurred:

Traceback (most recent call last):
  File "D:\Pland\backend\app\routers\infer.py", line 71, in predict_plant
    classifier = PlantClassifier(
                 ^^^^^^^^^^^^^^^^
  File "D:\Pland\backend\app\services\classifier.py", line 54, in __init__
    self._load_model()
  File "D:\Pland\backend\app\services\classifier.py", line 82, in _load_model
    self._load_default_model()
  File "D:\Pland\backend\app\services\classifier.py", line 116, in _load_default_model
    self.model = timm.create_model(
                 ^^^^^^^^^^^^^^^^^^
  File "D:\Pland\venv\Lib\site-packages\timm\models\_factory.py", line 113, in create_model
    raise RuntimeError('Unknown model (%s)' % model_name)
RuntimeError: Unknown model (efficientnet_b0_plant_whisperer)
2025-08-31 02:32:46,344 - app.main - ERROR - HTTP 500: 이미지 분석 중 오류가 발생했습니다.
2025-08-31 02:32:46,345 - app.main - ERROR - Unexpected error: 'dict' object is not callable
Traceback (most recent call last):
  File "D:\Pland\backend\app\services\classifier.py", line 108, in _load_pytorch_model
    self._load_default_model()
  File "D:\Pland\backend\app\services\classifier.py", line 116, in _load_default_model
    self.model = timm.create_model(
                 ^^^^^^^^^^^^^^^^^^
  File "D:\Pland\venv\Lib\site-packages\timm\models\_factory.py", line 113, in create_model
    raise RuntimeError('Unknown model (%s)' % model_name)
RuntimeError: Unknown model (efficientnet_b0_plant_whisperer)

During handling of the above exception, another exception occurred:

Traceback (most recent call last):
  File "D:\Pland\backend\app\services\classifier.py", line 78, in _load_model
    self._load_pytorch_model()
  File "D:\Pland\backend\app\services\classifier.py", line 111, in _load_pytorch_model
    self._load_default_model()
  File "D:\Pland\backend\app\services\classifier.py", line 116, in _load_default_model
    self.model = timm.create_model(
                 ^^^^^^^^^^^^^^^^^^
  File "D:\Pland\venv\Lib\site-packages\timm\models\_factory.py", line 113, in create_model
    raise RuntimeError('Unknown model (%s)' % model_name)
RuntimeError: Unknown model (efficientnet_b0_plant_whisperer)

During handling of the above exception, another exception occurred:

Traceback (most recent call last):
  File "D:\Pland\backend\app\routers\infer.py", line 71, in predict_plant
    classifier = PlantClassifier(
                 ^^^^^^^^^^^^^^^^
  File "D:\Pland\backend\app\services\classifier.py", line 54, in __init__
    self._load_model()
  File "D:\Pland\backend\app\services\classifier.py", line 82, in _load_model
    self._load_default_model()
  File "D:\Pland\backend\app\services\classifier.py", line 116, in _load_default_model
    self.model = timm.create_model(
                 ^^^^^^^^^^^^^^^^^^
  File "D:\Pland\venv\Lib\site-packages\timm\models\_factory.py", line 113, in create_model
    raise RuntimeError('Unknown model (%s)' % model_name)
RuntimeError: Unknown model (efficientnet_b0_plant_whisperer)

During handling of the above exception, another exception occurred:

Traceback (most recent call last):
  File "D:\Pland\venv\Lib\site-packages\starlette\middleware\exceptions.py", line 68, in __call__
    await self.app(scope, receive, sender)
  File "D:\Pland\venv\Lib\site-packages\fastapi\middleware\asyncexitstack.py", line 20, in __call__
    raise e
  File "D:\Pland\venv\Lib\site-packages\fastapi\middleware\asyncexitstack.py", line 17, in __call__
    await self.app(scope, receive, send)
  File "D:\Pland\venv\Lib\site-packages\starlette\routing.py", line 718, in __call__
    await route.handle(scope, receive, send)
  File "D:\Pland\venv\Lib\site-packages\starlette\routing.py", line 276, in handle
    await self.app(scope, receive, send)
  File "D:\Pland\venv\Lib\site-packages\starlette\routing.py", line 66, in app
    response = await func(request)
               ^^^^^^^^^^^^^^^^^^^
  File "D:\Pland\venv\Lib\site-packages\fastapi\routing.py", line 274, in app
    raw_response = await run_endpoint_function(
                   ^^^^^^^^^^^^^^^^^^^^^^^^^^^^
  File "D:\Pland\venv\Lib\site-packages\fastapi\routing.py", line 191, in run_endpoint_function
    return await dependant.call(**values)
           ^^^^^^^^^^^^^^^^^^^^^^^^^^^^^^
  File "D:\Pland\backend\app\routers\infer.py", line 118, in predict_plant
    raise HTTPException(
fastapi.exceptions.HTTPException

During handling of the above exception, another exception occurred:

Traceback (most recent call last):
  File "D:\Pland\venv\Lib\site-packages\starlette\middleware\errors.py", line 162, in __call__
    await self.app(scope, receive, _send)
  File "D:\Pland\venv\Lib\site-packages\starlette\middleware\cors.py", line 91, in __call__
    await self.simple_response(scope, receive, send, request_headers=headers)
  File "D:\Pland\venv\Lib\site-packages\starlette\middleware\cors.py", line 146, in simple_response
    await self.app(scope, receive, send)
  File "D:\Pland\venv\Lib\site-packages\starlette\middleware\exceptions.py", line 91, in __call__
    await response(scope, receive, sender)
          ^^^^^^^^^^^^^^^^^^^^^^^^^^^^^^^^
TypeError: 'dict' object is not callable
2025-08-31 02:33:20,178 - app.main - INFO - Shutting down Plant Whisperer Backend...
2025-08-31 02:33:48,347 - app.main - INFO - Starting Plant Whisperer Backend...
2025-08-31 02:33:48,352 - app.main - INFO - Backend startup complete
2025-08-31 02:34:07,694 - app.utils.io_utils - INFO - 파일 저장 완료: ./storage\29aa8d34-390b-45ae-865c-ac4190cfc331.jpg
2025-08-31 02:34:09,658 - app.services.preprocess - INFO - U²-Net 배경 제거 모델 로드 완료
2025-08-31 02:34:11,546 - timm.models._builder - INFO - Loading pretrained weights from Hugging Face hub (timm/efficientnet_b0.ra_in1k)
2025-08-31 02:34:15,123 - timm.models._hub - INFO - [timm/efficientnet_b0.ra_in1k] Safe alternative available for 'pytorch_model.bin' (as 'model.safetensors'). Loading weights using safetensors.
2025-08-31 02:34:15,160 - app.services.classifier - INFO - 기본 모델 로드 완료: efficientnet_b0
2025-08-31 02:35:04,459 - app.utils.io_utils - INFO - 파일 저장 완료: ./storage\e9f0de1d-572f-47c8-87aa-f95914885226.jpg
2025-08-31 02:35:04,464 - app.services.preprocess - INFO - U²-Net 배경 제거 모델 로드 완료
2025-08-31 02:35:06,177 - timm.models._builder - INFO - Loading pretrained weights from Hugging Face hub (timm/efficientnet_b0.ra_in1k)
2025-08-31 02:35:06,759 - timm.models._hub - INFO - [timm/efficientnet_b0.ra_in1k] Safe alternative available for 'pytorch_model.bin' (as 'model.safetensors'). Loading weights using safetensors.
2025-08-31 02:35:06,799 - app.services.classifier - INFO - 기본 모델 로드 완료: efficientnet_b0
2025-08-31 02:35:38,151 - app.main - INFO - Shutting down Plant Whisperer Backend...
2025-08-31 12:46:27,962 - app.main - INFO - Starting Plant Whisperer Backend...
2025-08-31 12:46:27,964 - app.main - INFO - Backend startup complete
2025-08-31 12:51:28,044 - app.utils.io_utils - INFO - 파일 저장 완료: ./storage\46b4d635-a407-4235-89ca-265abe791828.jpg
2025-08-31 12:51:33,185 - app.services.preprocess - INFO - U²-Net 배경 제거 모델 로드 완료
2025-08-31 12:51:35,610 - timm.models._builder - INFO - Loading pretrained weights from Hugging Face hub (timm/efficientnet_b0.ra_in1k)
2025-08-31 12:51:36,601 - timm.models._hub - INFO - [timm/efficientnet_b0.ra_in1k] Safe alternative available for 'pytorch_model.bin' (as 'model.safetensors'). Loading weights using safetensors.
2025-08-31 12:51:36,766 - app.services.classifier - INFO - 기본 모델 로드 완료: efficientnet_b0
2025-08-31 12:51:51,440 - app.utils.io_utils - INFO - 파일 저장 완료: ./storage\fbefb390-eadb-48fc-a228-a3561fc7ceb6.jpg
2025-08-31 12:51:51,474 - app.services.preprocess - INFO - U²-Net 배경 제거 모델 로드 완료
2025-08-31 12:51:53,668 - timm.models._builder - INFO - Loading pretrained weights from Hugging Face hub (timm/efficientnet_b0.ra_in1k)
2025-08-31 12:51:53,875 - timm.models._hub - INFO - [timm/efficientnet_b0.ra_in1k] Safe alternative available for 'pytorch_model.bin' (as 'model.safetensors'). Loading weights using safetensors.
2025-08-31 12:51:53,927 - app.services.classifier - INFO - 기본 모델 로드 완료: efficientnet_b0
2025-08-31 12:52:00,522 - app.utils.io_utils - INFO - 파일 저장 완료: ./storage\08e0f77f-c013-4089-ab1e-9a536ac43fb4.jpg
2025-08-31 12:52:00,561 - app.services.preprocess - INFO - U²-Net 배경 제거 모델 로드 완료
2025-08-31 12:52:02,363 - timm.models._builder - INFO - Loading pretrained weights from Hugging Face hub (timm/efficientnet_b0.ra_in1k)
2025-08-31 12:52:02,579 - timm.models._hub - INFO - [timm/efficientnet_b0.ra_in1k] Safe alternative available for 'pytorch_model.bin' (as 'model.safetensors'). Loading weights using safetensors.
2025-08-31 12:52:02,641 - app.services.classifier - INFO - 기본 모델 로드 완료: efficientnet_b0
2025-08-31 12:52:18,327 - app.utils.io_utils - INFO - 파일 저장 완료: ./storage\efc58a84-fd17-49c0-a973-adddca718df7.jpg
2025-08-31 12:52:18,366 - app.services.preprocess - INFO - U²-Net 배경 제거 모델 로드 완료
2025-08-31 12:52:20,206 - timm.models._builder - INFO - Loading pretrained weights from Hugging Face hub (timm/efficientnet_b0.ra_in1k)
2025-08-31 12:52:20,423 - timm.models._hub - INFO - [timm/efficientnet_b0.ra_in1k] Safe alternative available for 'pytorch_model.bin' (as 'model.safetensors'). Loading weights using safetensors.
2025-08-31 12:52:20,485 - app.services.classifier - INFO - 기본 모델 로드 완료: efficientnet_b0
2025-08-31 12:52:27,302 - app.utils.io_utils - INFO - 파일 저장 완료: ./storage\79d925d7-ec27-49d5-b383-f97874452c0b.jpg
2025-08-31 12:52:27,337 - app.services.preprocess - INFO - U²-Net 배경 제거 모델 로드 완료
2025-08-31 12:52:29,182 - timm.models._builder - INFO - Loading pretrained weights from Hugging Face hub (timm/efficientnet_b0.ra_in1k)
2025-08-31 12:52:29,398 - timm.models._hub - INFO - [timm/efficientnet_b0.ra_in1k] Safe alternative available for 'pytorch_model.bin' (as 'model.safetensors'). Loading weights using safetensors.
2025-08-31 12:52:29,453 - app.services.classifier - INFO - 기본 모델 로드 완료: efficientnet_b0
2025-08-31 12:59:47,671 - app.main - INFO - Shutting down Plant Whisperer Backend...
